Workbook

Sheet Assumptions
A5: Assumptions
A6: Driver Switch | B6: 3
A7: Assumptions
B8: NO. Campanies | F8: 2027 | G8: 2028 | H8: 2029
C9: NO. Campanies | F9: {=INDEX(F11:F13,$B$6)} -> 3 | G9: {=INDEX(G11:G13,$B$6)} -> 5 | H9: {=INDEX(H11:H13,$B$6)} -> 10
C11: Best Case | F11: 10 | G11: 15 | H11: 20
C12: Base Case | F12: 8 | G12: 10 | H12: 15
C13: Worst Case | F13: 3 | G13: 5 | H13: 10
B16: NO. Events | F16: =F8 -> 2027 | G16: =G8 -> 2028 | H16: =H8 -> 2029
C17: Event | F17: {=INDEX(F19:F21,$B$6)} -> 12 | G17: {=INDEX(G19:G21,$B$6)} -> 20 | H17: {=INDEX(H19:H21,$B$6)} -> 40
C19: Best Case | F19: =F11*7 -> 70 | G19: =G11*7 -> 105 | H19: =H11*7 -> 140
C20: Base Case | F20: =F12*5 -> 40 | G20: =G12*5 -> 50 | H20: =H12*5 -> 75
C21: Worst Case | F21: =F13*4 -> 12 | G21: =G13*4 -> 20 | H21: =H13*4 -> 40
B23: NO. Guests | F23: =F16 -> 2027 | G23: =G16 -> 2028 | H23: =H16 -> 2029
C24: NO Guests to spicial trip | F24: {=INDEX(F53:F55,$B$6)} -> 3600 | G24: {=INDEX(G53:G55,$B$6)} -> 6000 | H24: {=INDEX(H53:H55,$B$6)} -> 12000
B26: NO. Guests In Project | F26: =F23 -> 2027 | G26: =G23 -> 2028 | H26: =H23 -> 2029
C27: Best Case | F27: 200 | G27: 200 | H27: 200 | J27: نمو عدد الضيوف
C28: Base Case | F28: 150 | G28: 150 | H28: 150
C29: Worst Case | F29: 100 | G29: 100 | H29: 100
B31: Totel Of Guests | F31: =F26 -> 2027 | G31: =G26 -> 2028 | H31: =H26 -> 2029
C32: Best Case | F32: =F27*F19 -> 14000 | G32: =G27*G19 -> 21000 | H32: =H27*H19 -> 28000
C33: Base Case | F33: =F28*F20 -> 6000 | G33: =G28*G20 -> 7500 | H33: =H28*H20 -> 11250
C34: Worst Case | F34: =F21*F29 -> 1200 | G34: =G21*G29 -> 2000 | H34: =H21*H29 -> 4000
B38: Conversion | F38: =F31 -> 2027 | G38: =G31 -> 2028 | H38: =H31 -> 2029
C39: Best Case | F39: 0.5 | G39: 0.5 | H39: 0.5
C40: Base Case | F40: 0.25 | G40: 0.25 | H40: 0.25
C41: Worst Case | F41: 0.1 | G41: 0.1 | H41: 0.1
B44: AVG Cost Of The Trip | F44: =F38 -> 2027 | G44: =G38 -> 2028 | H44: =H38 -> 2029
C45: Best Case | F45: 30 | G45: 30 | H45: 30
C46: Base Case | F46: 30 | G46: 30 | H46: 30
C47: Worst Case | F47: 30 | G47: 30 | H47: 30
F49: =F44 -> 2027 | G49: =G44 -> 2028 | H49: =H44 -> 2029
C50: Revenue Of The Trip | F50: {=INDEX(F53:F55,$B$6)} -> 3600 | G50: {=INDEX(G53:G55,$B$6)} -> 6000 | H50: {=INDEX(H53:H55,$B$6)} -> 12000
B52: Revenue Of The Trip | F52: =F49 -> 2027 | G52: =G49 -> 2028 | H52: =H49 -> 2029
C53: Best Case | F53: =F45*F39*F32 -> 210000 | G53: =G45*G39*G32 -> 315000 | H53: =H45*H39*H32 -> 420000
C54: Base Case | F54: =F46*F40*F33 -> 45000 | G54: =G46*G40*G33 -> 56250 | H54: =H46*H40*H33 -> 84375
C55: Worst Case | F55: =F47*F41*F34 -> 3600 | G55: =G47*G41*G34 -> 6000 | H55: =H47*H41*H34 -> 12000
B57: Event volume | F57: =F52 -> 2027 | G57: =G52 -> 2028 | H57: =H52 -> 2029
C58: Cars | F58: {=INDEX(F63:F65,$B$6)} -> 327600 | G58: {=INDEX(G63:G65,$B$6)} -> 546000 | H58: {=INDEX(H63:H65,$B$6)} -> 1092000
C59: Tickit | F59: {=INDEX(F68:F70,$B$6)} -> 147000 | G59: {=INDEX(G68:G70,$B$6)} -> 245000 | H59: {=INDEX(H68:H70,$B$6)} -> 490000
...

Sheet Income statement
A1: Income Statemaent
C2: Revenue
D3: =Assumptions!C58 -> Cars | H3: =Assumptions!F58 -> 327600 | I3: =Assumptions!G58 -> 546000 | J3: =Assumptions!H58 -> 1092000
D4: =Assumptions!C59 -> Tickit | H4: =Assumptions!F59 -> 147000 | I4: =Assumptions!G59 -> 245000 | J4: =Assumptions!H59 -> 490000
D5: =Assumptions!C60 -> Hotels | H5: =Assumptions!F60 -> 384000 | I5: =Assumptions!G60 -> 640000 | J5: =Assumptions!H60 -> 1280000
C6: Total Revenue | H6: =SUM(H3:H5) -> 858600 | I6: =SUM(I3:I5) -> 1431000 | J6: =SUM(J3:J5) -> 2862000
C7: Cost Of Revenue
D8: SMS / OTP | H8: =Assumptions!F130 -> 3000 | I8: =Assumptions!G130 -> 5000 | J8: =Assumptions!H130 -> 10000
D9: Email API | H9: =Assumptions!F132 -> 188 | I9: =Assumptions!G132 -> 188 | J9: =Assumptions!H132 -> 188
D10: Maps API | H10: =Assumptions!F134 -> 4800 | I10: =Assumptions!G134 -> 8000 | J10: =Assumptions!H134 -> 16000
D11: AI API Usage | H11: =Assumptions!F136 -> 3600 | I11: =Assumptions!G136 -> 6000 | J11: =Assumptions!H136 -> 12000
D12: Storage | H12: =Assumptions!F138 -> 2400 | I12: =Assumptions!G138 -> 3600 | J12: =Assumptions!H138 -> 6000
D13: Push Notifications API | H13: =Assumptions!F140 -> 600 | I13: =Assumptions!G140 -> 1000 | J13: =Assumptions!H140 -> 2000
D14: CDN | H14: =Assumptions!F142 -> 2400 | I14: =Assumptions!G142 -> 3600 | J14: =Assumptions!H142 -> 6000
C15: Total Cost | H15: =SUM(H8:H14) -> 16988 | I15: =SUM(I8:I14) -> 27388 | J15: =SUM(J8:J14) -> 52188
C16: Grose Profit | H16: =H6-H15 -> 841612 | I16: =I6-I15 -> 1403612 | J16: =J6-J15 -> 2809812
C17: Operating Expenses
D18: Founder / CEO | H18: =Assumptions!F109 -> 240000 | I18: =Assumptions!G109 -> 240000 | J18: =Assumptions!H109 -> 240000
D19: Full Stack Developer | H19: =Assumptions!F110 -> 240000 | I19: =Assumptions!G110 -> 240000 | J19: =Assumptions!H110 -> 240000
D20: Mobile Developer | H20: =Assumptions!F111 -> 240000 | I20: =Assumptions!G111 -> 240000 | J20: =Assumptions!H111 -> 240000
D21: UI/UX Designer | H21: =Assumptions!F112 -> 60000 | I21: =Assumptions!G112 -> 0 | J21: =Assumptions!H112 -> 0
D22: QA Engineer | H22: =Assumptions!F113 -> 48000 | I22: =Assumptions!G113 -> 0 | J22: =Assumptions!H113 -> 0
D23: DevOps Engineer | H23: =Assumptions!F114 -> 30000 | I23: =Assumptions!G114 -> 0 | J23: =Assumptions!H114 -> 0
D24: Product / Operations Lead | H24: =Assumptions!F115 -> 216000 | I24: =Assumptions!G115 -> 216000 | J24: =Assumptions!H115 -> 216000
D25: Customer Support | H25: =Assumptions!F116 -> 21000 | I25: =Assumptions!G116 -> 84000 | J25: =Assumptions!H116 -> 84000
D26: Business Development Manager | H26: =Assumptions!F117 -> 60000 | I26: =Assumptions!G117 -> 180000 | J26: =Assumptions!H117 -> 180000
D27: Digital Marketer | H27: =Assumptions!F118 -> 40000 | I27: =Assumptions!G118 -> 120000 | J27: =Assumptions!H118 -> 120000
D28: Sales Manager | H28: =Assumptions!F119 -> 0 | I28: =Assumptions!G119 -> 192000 | J28: =Assumptions!H119 -> 192000
D29: Accountant | H29: =Assumptions!F120 -> 84000 | I29: =Assumptions!G120 -> 84000 | J29: =Assumptions!H120 -> 84000
... D31: AI / ML Engineer | H31: =Assumptions!F122 -> 300000 | I31: =Assumptions!G122 -> 300000 | J31: =Assumptions!H122 -> 300000
D32: Office Rent | H32: =Assumptions!F144 -> 60000 | I32: =Assumptions!G144 -> 60000 | J32: =Assumptions!H144 -> 60000
D33: Internet | H33: =Assumptions!F145 -> 3600 | I33: =Assumptions!G145 -> 3600 | J33: =Assumptions!H145 -> 3600
D34: Utilities | H34: =Assumptions!F146 -> 6000 | I34: =Assumptions!G146 -> 6000 | J34: =Assumptions!H146 -> 6000
D35: Furniture | H35: =Assumptions!F147 -> 50000 | I35: =Assumptions!G147 -> 2500 | J35: =Assumptions!H147 -> 2500
D36: Laptops | H36: =Assumptions!F148 -> 42000 | I36: =Assumptions!G148 -> 1000 | J36: =Assumptions!H148 -> 5000
D37: Office Supplies | H37: =Assumptions!F149 -> 1800 | I37: =Assumptions!G149 -> 1800 | J37: =Assumptions!H149 -> 1800
D38: Software Tools | H38: =Assumptions!F150 -> 4800 | I38: =Assumptions!G150 -> 4800 | J38: =Assumptions!H150 -> 4800
D39: Maintenance | H39: =Assumptions!F151 -> 24000 | I39: =Assumptions!G151 -> 24000 | J39: =Assumptions!H151 -> 24000
D40: Hosting / Cloud | H40: =Assumptions!F152 -> 36000 | I40: =Assumptions!G152 -> 48000 | J40: =Assumptions!H152 -> 72000
D41: DevOps Part-time | H41: =Assumptions!F153 -> 3000 | I41: =Assumptions!G153 -> 3000 | J41: =Assumptions!H153 -> 3000
...

Sheet clarifications
A1: ما في تكلفة صيانة سنوية
B2: Payment Gateway Fees هل بنحتاجه
A3: ما في تكلفة سيرفرات
A5: ما في تكلفة AI
A7: ما في تكلفة DevOps / Security
A9: ما في تكلفة Hosting
A11: ما في تكلفة Integrations (خرائط – SMS – OTP – Email)
A16: SMS / OTP | B16: رسائل التحقق (OTP) و رسائل تحديثات الضيوف و رسائل للسائقين و رسائل تأكيد الحجوزات
A18: Email API | B18: إرسال الإيميلات للضيوف تأكيد الدعوات إرسال الفواتير إشعارات النظام | J18: كل اربعه يوف سياره
J19: كل ضيف VIP سياره
A20: Maps API (خرائط – تتبع – حساب مسافات) | B20: في الفعاليات الكبيرة (تتبع مستمر): 3,000 – 10,000 ريال | J20: كل 70 ضيف سيارة قولف
J21: كل 150 ضيف حاويه
A22: AI API Usage (مثل OpenAI) | B22: تشغيل المرشد الذكي "سعود" الردود الذكية الترجمة تحليل الطلبات تلخيص البيانات | J22: كل 200 ضيف سيارة شحن
J23: كل 300 ضيف معدات ثقيله
A24: Payment Gateway Fees | B24: رسوم بوابة الدفع عند: شراء تذاكر دفع خدمات حجوزات Marketplace
A26: Storage للصور والفواتير | J26: اسئله
J27: كم نسبه وكالات السفر في التذكره
A28: CDN للاستخدام العالي | B28: سريع تحميل الصور تسريع تحميل الملفات تحسين أداء التطبيقات Cloudflare / AWS CloudFront
J29: نصيحه
J30: Developer واحد
J31: Operations قوي جدًا
J32: Sales ذكي
A34: A) الرواتب (Salaries) | J34: ❌ لا تبني فريق كبير تقني من البداية
C35: كلما زاد عدد الضيوف زادت المصاريف
A36: Full Stack Developer | C36: المشكلة الثانية — تكاليف التقنية ثابتة وغير مرتبطة بالحجم تكاليف الخرائط والرسائل القصيرة والذكاء الاصطناعي جميعها ثابتة سنوياً بصرف النظر عن عدد الضيوف. هذا خطأ كبير، لأن هذه التكاليف تزداد مع كل ضيف وكل فعالية. عند 11,250 ضيف في السيناريو المتوسط لسنة 2029، تكاليف الخرائط وحدها ستكون أضعاف الرقم المذكور.
C37: اقتراحي أن تضع باقتين، الأولى مجانية بعمولة 18% وبدون أولوية ظهور، والثانية باشتراك بين 500 و 1,000 ريال شهرياً بعمولة 10% وبأولوية الظهور. هذا الرقم يغطي جزءاً من تكاليفك التشغيلية المباشرة ويعطي المورد حافزاً واضحاً للاشتراك.
A38: UI/UX Designer
A40: Product Architect (دمج PM + Ops Lead)
A42: Business Development
A44: Customer Support
A46: Accountant (Outsource)
A48: B) البنية التحتية التقنية (Infrastructure)
A50: Hosting / Servers (AWS / Azure / GCP)
A52: Database
A54: Backups
A56: Monitoring (Sentry / Datadog)
A58: Analytics (Mixpanel / Amplitude)
A60: DevOps (Part-time)
... A168: اجتماعات حكومية
