Workbook

Sheet Income Statement
A1: Mudyaf — Income Statement | 2027–2029 (Base Case, SAR)
A2: Item | B2: 2027 | C2: 2028 | D2: 2029
A3: REVENUE
A4: Cars Commission | B4: =Assumptions!F44 -> 1638000 | C4: =Assumptions!G44 -> 3369600 | D4: =Assumptions!H44 -> 6065280
A5: Tickets Commission | B5: =Assumptions!F51 -> 1646400 | C5: =Assumptions!G51 -> 3386880 | D5: =Assumptions!H51 -> 6096384
A6: Hotels Commission | B6: =Assumptions!F58 -> 2688000 | C6: =Assumptions!G58 -> 5529600 | D6: =Assumptions!H58 -> 9953280
A7: Total Revenue | B7: =B4+B5+B6 -> 5972400 | C7: =C4+C5+C6 -> 12286080 | D7: =D4+D5+D6 -> 22114944
A8: COST OF REVENUE (Direct — Variable with Guests)
A9: SMS / OTP | B9: =Assumptions!C109 -> 4200 | C9: =Assumptions!D109 -> 8640 | D9: =Assumptions!F109 -> 15552
A10: Email API | B10: =Assumptions!C110 -> 84 | C10: =Assumptions!D110 -> 172.8 | D10: =Assumptions!F110 -> 311.04
A11: Maps API | B11: =Assumptions!C111 -> 1092 | C11: =Assumptions!D111 -> 2246.4 | D11: =Assumptions!F111 -> 4043.52
A12: AI API Usage | B12: =Assumptions!C112 -> 504 | C12: =Assumptions!D112 -> 1036.8 | D12: =Assumptions!F112 -> 1866.24
A13: Translation AI | B13: =Assumptions!C113 -> 336 | C13: =Assumptions!D113 -> 691.2 | D13: =Assumptions!F113 -> 1244.16
A14: WhatsApp API | B14: =Assumptions!C114 -> 10080 | C14: =Assumptions!D114 -> 20736 | D14: =Assumptions!F114 -> 37324.8
A15: Storage | B15: =Assumptions!C115 -> 16800 | C15: =Assumptions!D115 -> 34560 | D15: =Assumptions!F115 -> 62208
A16: Push Notifications | B16: =Assumptions!C116 -> 336 | C16: =Assumptions!D116 -> 691.2 | D16: =Assumptions!F116 -> 1244.16
A17: CDN | B17: =Assumptions!C117 -> 4200 | C17: =Assumptions!D117 -> 8640 | D17: =Assumptions!F117 -> 15552
A18: Total Cost of Revenue | B18: =SUM(B9:B17) -> 37632 | C18: =SUM(C9:C17) -> 77414.4 | D18: =SUM(D9:D17) -> 139345.92
A19: Gross Profit | B19: =B7-B18 -> 5934768 | C19: =C7-C18 -> 12208666 | D19: =D7-D18 -> 21975598
A20: Gross Margin % | B20: =B19/B7 -> 0.99369902 | C20: =C19/C7 -> 0.99369902 | D20: =D19/D7 -> 0.99369902
A22: OPERATING EXPENSES (Fixed)
A23: Salaries & Benefits (excl. GOSI) | B23: =Assumptions!D104 -> 1200000 | C23: =Assumptions!F104 -> 1374000 | D23: =Assumptions!G104 -> 1576200
A24: GOSI — Social Insurance 11% | B24: =B23*0.11 -> 132000 | C24: =C23*0.11 -> 151140 | D24: =D23*0.11 -> 173382
A25: Indirect Costs | B25: =Assumptions!C139 -> 217400 | C25: =Assumptions!D139 -> 287400 | D25: =Assumptions!F139 -> 387200
A26: Technology Maintenance | B26: =Assumptions!C146 -> 85000 | C26: =Assumptions!D146 -> 146000 | D26: =Assumptions!F146 -> 225000
A27: Sales & Marketing | B27: =Assumptions!C156 -> 591000 | C27: =Assumptions!D156 -> 389000 | D27: =Assumptions!F156 -> 452000
A28: Total Operating Expenses | B28: =SUM(B23:B27) -> 2225400 | C28: =SUM(C23:C27) -> 2347540 | D28: =SUM(D23:D27) -> 2813782
A30: EBITDA | B30: =B19-B28 -> 3709368 | C30: =C19-C28 -> 9861125.6 | D30: =D19-D28 -> 19161816
A31: EBITDA Margin % | B31: =B30/B7 -> 0.62108499 | C31: =C30/C7 -> 0.80262587 | D31: =D30/D7 -> 0.8664646
A32: (-) Depreciation | B32: =Assumptions!F164 -> 210666.67 | C32: =Assumptions!G164 -> 210666.67 | D32: =Assumptions!H164 -> 210666.67
A33: EBIT | B33: =B30-B32 -> 3498701.3 | C33: =C30-C32 -> 9650458.9 | D33: =D30-D32 -> 18951149
A34: (-) Zakat 2.5% | B34: =MAX(B33,0)*0.025 -> 87467.533 | C34: =MAX(C33,0)*0.025 -> 241261.47 | D34: =MAX(D33,0)*0.025 -> 473778.74
A35: Net Profit | B35: =B33-B34 -> 3411233.8 | C35: =C33-C34 -> 9409197.5 | D35: =D33-D34 -> 18477371
A36: Net Profit Margin % | B36: =B35/B7 -> 0.57116633 | C36: =C35/C7 -> 0.76584211 | D36: =D35/D7 -> 0.83551515
A38: Note: Zakat calculated at 2.5% of EBIT (simplified). Actual Zakat base per ZATCA regulations may differ — consult a certified Zakat advisor. GOSI = 11% employer contribution (9% social insurance + 2% labor insurance) applied to all Saudi nationals.
A40: Note on Cloud Infrastructure & Unit Economics: Cost of Revenue includes dynamic variable scaling per guest for WhatsApp API, SMS OTP, AI API usage (سيف ومنيره), and SCCC/TopNet Object Storage & CDN. Fixed Operating Expenses include dedicated SCCC / TopNet High-Availability Kubernetes and PostgreSQL RDS database clusters.

Sheet Cash Flow
A1: Mudyaf — Cash Flow Statement | 2026–2029 (SAR)
A2: Year | B2: 2026 | C2: 2027 | D2: 2028 | E2: 2029
A3: OPERATING ACTIVITIES
A4: Pre-launch startup & operating costs 2026 | B4: =-Assumptions!D182 -> -2093400 | C4: - | D4: - | E4: -
A5: Net Profit | B5: - | C5: ='Income Statement'!B35 -> 3411233.8 | D5: ='Income Statement'!C35 -> 9409197.5 | E5: ='Income Statement'!D35 -> 18477371
A6: (+) Depreciation (non-cash add-back) | B6: - | C6: ='Income Statement'!B32 -> 210666.67 | D6: ='Income Statement'!C32 -> 210666.67 | E6: ='Income Statement'!D32 -> 210666.67
A7: (-) Change in Accounts Receivable | B7: - | C7: =-'Income Statement'!B7*Assumptions!B175/365 -> -1472646.6 | D7: =-('Income Statement'!C7-'Income Statement'!B7)*Assumptions!B175/365 -> -1556797.8 | E7: =-('Income Statement'!D7-'Income Statement'!C7)*Assumptions!B175/365 -> -2423555.5
A8: (+) Change in Accounts Payable [CORRECTED: based on COR, not Revenue] | B8: - | C8: ='Income Statement'!B18*Assumptions!B176/365 -> 6186.0822 | D8: =('Income Statement'!C18-'Income Statement'!B18)*Assumptions!B176/365 -> 6539.5726 | E8: =('Income Statement'!D18-'Income Statement'!C18)*Assumptions!B176/365 -> 10180.524
A9: (+) Change in Zakat Payable | B9: - | C9: ='Income Statement'!B34 -> 87467.533 | D9: ='Income Statement'!C34-'Income Statement'!B34 -> 153793.94 | E9: ='Income Statement'!D34-'Income Statement'!C34 -> 232517.26
A10: Operating Cash Flow | B10: =B4 -> -2093400 | C10: =SUM(C5:C9) -> 2242907.5 | D10: =SUM(D5:D9) -> 8223399.8 | E10: =SUM(E5:E9) -> 16507180
A12: INVESTING ACTIVITIES
A13: Purchase of PP&E (Furniture + Devices) | B13: =-Assumptions!H169 -> -92000 | C13: - | D13: - | E13: -
A14: Investment in Intangible Assets (Platform + AI Dev) | B14: =-Assumptions!H90 -> -900000 | C14: - | D14: - | E14: -
A15: Investing Cash Flow | B15: =SUM(B13:B14) -> -992000 | C15: - | D15: - | E15: -
A17: FINANCING ACTIVITIES
A18: Equity Injection from Investor | B18: =Assumptions!D184 -> 3393940 | C18: - | D18: - | E18: -
A19: Financing Cash Flow | B19: =B18 -> 3393940 | C19: - | D19: - | E19: -
A21: Net Change in Cash | B21: =B10+B15+B19 -> 308540 | C21: =C10 -> 2242907.5 | D21: =D10 -> 8223399.8 | E21: =E10 -> 16507180
A22: Opening Cash Balance | B22: 0 | C22: =B23 -> 308540 | D22: =C23 -> 2551447.5 | E22: =D23 -> 10774847
A23: Closing Cash Balance | B23: =B22+B21 -> 308540 | C23: =C22+C21 -> 2551447.5 | D23: =D22+D21 -> 10774847 | E23: =E22+E21 -> 27282027
A25: CORRECTION APPLIED: The original model used Revenue as the AP base, creating a ~988K SAR error per year in cash flow and balance sheet imbalance. AP change is now correctly calculated on Cost of Revenue (direct costs). Additionally, Retained Earnings is now cumulative across years, fixing the balance sheet balance.

Sheet Balance Sheet
A1: Mudyaf — Balance Sheet (Statement of Financial Position) | 2027–2029 (SAR)
A2: Item | B2: 2027 | C2: 2028 | D2: 2029
A3: ASSETS
A4: Current Assets
A5: Cash & Cash Equivalents | B5: ='Cash Flow'!C23 -> 2551447.5 | C5: ='Cash Flow'!D23 -> 10774847 | D5: ='Cash Flow'!E23 -> 27282027
A6: Accounts Receivable | B6: ='Income Statement'!B7*Assumptions!B175/365 -> 1472646.6 | C6: ='Income Statement'!C7*Assumptions!B175/365 -> 3029444.4 | D6: ='Income Statement'!D7*Assumptions!B175/365 -> 5452999.9
A7: VAT Receivable (collected not yet remitted to ZATCA) | B7: ='Income Statement'!B7/12*Assumptions!B174 -> 74655 | C7: ='Income Statement'!C7/12*Assumptions!B174 -> 153576 | D7: ='Income Statement'!D7/12*Assumptions!B174 -> 276436.8
A8: Total Current Assets | B8: =B5+B6+B7 -> 4098749.1 | C8: =C5+C6+C7 -> 13957868 | D8: =D5+D6+D7 -> 33011464
A10: Non-Current Assets
A11: PP&E Net (Furniture & Devices) | B11: =Assumptions!H169-(Assumptions!F160+Assumptions!F161) -> 61333.333 | C11: =Assumptions!H169-2*(Assumptions!F160+Assumptions!F161) -> 30666.667 | D11: =Assumptions!H169-3*(Assumptions!F160+Assumptions!F161) -> 0
A12: Intangible Assets Net (Platform + AI) | B12: =Assumptions!H90-Assumptions!F162-Assumptions!F163 -> 720000 | C12: =Assumptions!H90-2*Assumptions!F162-2*Assumptions!F163 -> 540000 | D12: =Assumptions!H90-3*Assumptions!F162-3*Assumptions!F163 -> 360000
A13: Total Non-Current Assets | B13: =B11+B12 -> 781333.33 | C13: =C11+C12 -> 570666.67 | D13: =D11+D12 -> 360000
A15: TOTAL ASSETS | B15: =B8+B13 -> 4880082.4 | C15: =C8+C13 -> 14528534 | D15: =D8+D13 -> 33371464
A17: LIABILITIES
A18: Current Liabilities
A19: Accounts Payable | B19: ='Income Statement'!B18*Assumptions!B176/365 -> 6186.0822 | C19: ='Income Statement'!C18*Assumptions!B176/365 -> 12725.655 | D19: ='Income Statement'!D18*Assumptions!B176/365 -> 22906.179
A20: Zakat Payable | B20: ='Income Statement'!B34 -> 87467.533 | C20: ='Income Statement'!C34 -> 241261.47 | D20: ='Income Statement'!D34 -> 473778.74
A21: VAT Payable (1-month estimate) | B21: ='Income Statement'!B7/12*Assumptions!B174 -> 74655 | C21: ='Income Statement'!C7/12*Assumptions!B174 -> 153576 | D21: ='Income Statement'!D7/12*Assumptions!B174 -> 276436.8
A22: Total Liabilities | B22: =B19+B20+B21 -> 168308.62 | C22: =C19+C20+C21 -> 407563.13 | D22: =D19+D20+D21 -> 773121.71
A24: EQUITY
A25: Paid-in Capital | B25: =Assumptions!D184 -> 3393940 | C25: =Assumptions!D184 -> 3393940 | D25: =Assumptions!D184 -> 3393940
A26: Accumulated Losses — Pre-operating Phase | B26: =-Assumptions!D182 -> -2093400 | C26: =-Assumptions!D182 -> -2093400 | D26: =-Assumptions!D182 -> -2093400
A27: Retained Earnings (Cumulative) [CORRECTED] | B27: ='Income Statement'!B35 -> 3411233.8 | C27: ='Income Statement'!B35+'Income Statement'!C35 -> 12820431 | D27: ='Income Statement'!B35+'Income Statement'!C35+'Income Statement'!D35 -> 31297802
A28: Total Equity | B28: =B25+B26+B27 -> 4711773.8 | C28: =C25+C26+C27 -> 14120971 | D28: =D25+D26+D27 -> 32598342
A30: TOTAL LIABILITIES + EQUITY | B30: =B22+B28 -> 4880082.4 | C30: =C22+C28 -> 14528534 | D30: =D22+D28 -> 33371464
A31: ✓ Balance Check (must be 0) | B31: =B15-B30 -> 0 | C31: =C15-C30 -> 0 | D31: =D15-D30 -> 0
A33: TWO CORRECTIONS APPLIED: (1) Retained Earnings is now cumulative (sum of all prior net profits), fixing the year-over-year equity rollforward. (2) AP base changed from Revenue to Cost of Revenue — AP represents what we OWE to tech vendors/API providers, which scales with direct costs, not total revenue. (3) Added VAT Payable as a liability (1 month of revenue × 15% VAT rate).

Sheet Assumptions
A1: Assumptions
A5: From here, you select the scenario whose numbers you want to use.
A6: Driver Switch | B6: 2
A7: Here we estimate the number of events and the number of guests
B8: NO. Campanies | F8: 2027 | G8: 2028 | H8: 2029
C9: NO. Campanies | F9: {=INDEX(F11:F13,$B$6)} -> 8 | G9: {=INDEX(G11:G13,$B$6)} -> 12 | H9: {=INDEX(H11:H13,$B$6)} -> 16
C11: Best Case | F11: 10 | G11: 15 | H11: 20
C12: Base Case | F12: 8 | G12: 12 | H12: 16
C13: Worst Case | F13: 3 | G13: 5 | H13: 10
B16: NO. Events | F16: =F8 -> 2027 | G16: =G8 -> 2028 | H16: =H8 -> 2029
C17: Event | F17: {=INDEX(F19:F21,$B$6)} -> 56 | G17: {=INDEX(G19:G21,$B$6)} -> 96 | H17: {=INDEX(H19:H21,$B$6)} -> 144
C19: Best Case | F19: =F11*10 -> 100 | G19: =G11*11 -> 165 | H19: =H11*12 -> 240
C20: Base Case | F20: =F12*7 -> 56 | G20: =G12*8 -> 96 | H20: =H12*9 -> 144
C21: Worst Case | F21: =F13*4 -> 12 | G21: =G13*5 -> 25 | H21: =H13*6 -> 60
B23: NO. Guests | F23: =F16 -> 2027 | G23: =G16 -> 2028 | H23: =H16 -> 2029
C24: Total Expected Guests | F24: {=INDEX(F32:F34,$B$6)} -> 8400 | G24: {=INDEX(G32:G34,$B$6)} -> 17280 | H24: {=INDEX(H32:H34,$B$6)} -> 31104
B26: NO. Guests In Project | F26: =F23 -> 2027 | G26: =G23 -> 2028 | H26: =H23 -> 2029
C27: Best Case | F27: 200 | G27: =F27*(1+20%) -> 240 | H27: =G27*(1+20%) -> 288
C28: Base Case | F28: 150 | G28: =F28*(1+20%) -> 180 | H28: =G28*(1+20%) -> 216
C29: Worst Case | F29: 100 | G29: =F29*(1+20%) -> 120 | H29: =G29*(1+20%) -> 144
B31: Totel Of Guests | F31: =F26 -> 2027 | G31: =G26 -> 2028 | H31: =H26 -> 2029
C32: Best Case | F32: =F27*F19 -> 20000 | G32: =G27*G19 -> 39600 | H32: =H27*H19 -> 69120
C33: Base Case | F33: =F28*F20 -> 8400 | G33: =G28*G20 -> 17280 | H33: =H28*H20 -> 31104
C34: Worst Case | F34: =F21*F29 -> 1200 | G34: =G21*G29 -> 3000 | H34: =H21*H29 -> 8640
A37: Here we will estimate the app’s revenue from each event.
F39: Cars | G39: Tickit | H39: Hotels
B40: Commission rates by scenario | F40: 0.1 | G40: 0.08 | H40: 0.1
B42: cars | F42: 2027 | G42: 2028 | H42: 2029
C43: Best Case | F43: =((((F27/4)*F19)*1300)*$F$40)*6 -> 3900000 | G43: =((((G27/4)*G19)*1300)*$F$40)*6 -> 7722000 | H43: =((((H27/4)*H19)*1300)*$F$40)*6 -> 13478400
C44: Base Case | F44: =((((F28/4)*F20)*1300)*$F$40)*6 -> 1638000 | G44: =((((G28/4)*G20)*1300)*$F$40)*6 -> 3369600 | H44: =((((H28/4)*H20)*1300)*$F$40)*6 -> 6065280
C45: Worst Case | F45: =((((F29/4)*F21)*1300)*$F$40)*6 -> 234000 | G45: =((((G29/4)*G21)*1300)*$F$40)*6 -> 585000 | H45: =((((H29/4)*H21)*1300)*$F$40)*6 -> 1684800
B49: Tickit | F49: =F42 -> 2027 | G49: =G42 -> 2028 | H49: =H42 -> 2029
C50: Best Case | F50: =((F32*70%)*3500)*$G$40 -> 3920000 | G50: =((G32*70%)*3500)*$G$40 -> 7761600 | H50: =((H32*70%)*3500)*$G$40 -> 13547520
C51: Base Case | F51: =((F33*70%)*3500)*$G$40 -> 1646400 | G51: =((G33*70%)*3500)*$G$40 -> 3386880 | H51: =((H33*70%)*3500)*$G$40 -> 6096384
C52: Worst Case | F52: =((F34*70%)*3500)*$G$40 -> 235200 | G52: =((G34*70%)*3500)*$G$40 -> 588000 | H52: =((H34*70%)*3500)*$G$40 -> 1693440
B56: Hotels | F56: =F49 -> 2027 | G56: =G49 -> 2028 | H56: =H49 -> 2029
C57: Best Case | F57: =(F32/1.5)*1200*4*$H$40 -> 6400000 | G57: =(G32/1.5)*1200*4*$H$40 -> 12672000 | H57: =(H32/1.5)*1200*4*$H$40 -> 22118400
C58: Base Case | F58: =(F33/1.5)*1200*4*$H$40 -> 2688000 | G58: =(G33/1.5)*1200*4*$H$40 -> 5529600 | H58: =(H33/1.5)*1200*4*$H$40 -> 9953280
C59: Worst Case | F59: =(F34/1.5)*1200*4*$H$40 -> 384000 | G59: =(G34/1.5)*1200*4*$H$40 -> 960000 | H59: =(H34/1.5)*1200*4*$H$40 -> 2764800
B63: Event volume | F63: 2027 | G63: 2028 | H63: 2029
...

Sheet output
A1: Income Statemaent
C2: Revenue | H2: 2027 | I2: 2028 | J2: 2029
D3: =Assumptions!C64 -> Cars | H3: =Assumptions!F64 -> 1638000 | I3: =Assumptions!G64 -> 3369600 | J3: =Assumptions!H64 -> 6065280
D4: =Assumptions!C65 -> Tickit | H4: =Assumptions!F65 -> 1646400 | I4: =Assumptions!G65 -> 3386880 | J4: =Assumptions!H65 -> 6096384
D5: =Assumptions!C66 -> Hotels | H5: =Assumptions!F66 -> 2688000 | I5: =Assumptions!G66 -> 5529600 | J5: =Assumptions!H66 -> 9953280
C6: Total Revenue | H6: =SUM(H3:H5) -> 5972400 | I6: =SUM(I3:I5) -> 12286080 | J6: =SUM(J3:J5) -> 22114944
C7: Cost Of Revenue
D8: =Assumptions!B109 -> SMS / OTP Verification API (Taqnyat/Unifonic) | H8: =Assumptions!C109 -> 4200 | I8: =Assumptions!D109 -> 8640 | J8: =Assumptions!F109 -> 15552
D9: =Assumptions!B110 -> Email API | H9: =Assumptions!C110 -> 84 | I9: =Assumptions!D110 -> 172.8 | J9: =Assumptions!F110 -> 311.04
D10: =Assumptions!B111 -> Maps API | H10: =Assumptions!C111 -> 1092 | I10: =Assumptions!D111 -> 2246.4 | J10: =Assumptions!F111 -> 4043.52
D11: =Assumptions!B112 -> AI API Usage | H11: =Assumptions!C112 -> 504 | I11: =Assumptions!D112 -> 1036.8 | J11: =Assumptions!F112 -> 1866.24
D12: =Assumptions!B113 -> Translation AI | H12: =Assumptions!C113 -> 336 | I12: =Assumptions!D113 -> 691.2 | J12: =Assumptions!F113 -> 1244.16
D13: =Assumptions!B114 -> WhatsApp Business API & Bot Messaging (Meta/Twilio) | H13: =Assumptions!C114 -> 10080 | I13: =Assumptions!D114 -> 20736 | J13: =Assumptions!F114 -> 37324.8
D14: =Assumptions!B115 -> SCCC / TopNet Cloud Storage (OSS & Media Files per guest) | H14: =Assumptions!C115 -> 16800 | I14: =Assumptions!D115 -> 34560 | J14: =Assumptions!F115 -> 62208
D15: =Assumptions!B116 -> Push Notifications | H15: =Assumptions!C116 -> 336 | I15: =Assumptions!D116 -> 691.2 | J15: =Assumptions!F116 -> 1244.16
D16: =Assumptions!B117 -> Cloud CDN & Edge Bandwidth (SCCC / TopNet Edge) | H16: =Assumptions!C117 -> 4200 | I16: =Assumptions!D117 -> 8640 | J16: =Assumptions!F117 -> 15552
C17: Total Cost | H17: =SUM(H8:H16) -> 37632 | I17: =SUM(I8:I16) -> 77414.4 | J17: =SUM(J8:J16) -> 139345.92
C18: Grose Profit | H18: =H6-H17 -> 5934768 | I18: =I6-I17 -> 12208666 | J18: =J6-J17 -> 21975598
C19: Gross Margin | H19: =H18/H6 -> 0.99369902 | I19: =I18/I6 -> 0.99369902 | J19: =J18/J6 -> 0.99369902
C20: Operating Expenses
D21: Salaries & Wages | H21: =Assumptions!$D$104 -> 1200000 | I21: =Assumptions!F104 -> 1374000 | J21: =Assumptions!G104 -> 1576200
D22: Indirect cost | H22: =Assumptions!C139 -> 217400 | I22: =Assumptions!D139 -> 287400 | J22: =Assumptions!$F$139 -> 387200
D23: Technology Cost Assumptions | H23: =Assumptions!C146 -> 85000 | I23: =Assumptions!D146 -> 146000 | J23: =Assumptions!$F$146 -> 225000
D24: Sales & Marketing Expenses | H24: =Assumptions!C156 -> 591000 | I24: =Assumptions!D156 -> 389000 | J24: =Assumptions!$F$156 -> 452000
D25: Depreciation | H25: =Assumptions!F164 -> 210666.67 | I25: =Assumptions!G164 -> 210666.67 | J25: =Assumptions!H164 -> 210666.67
C26: Total Expenses | H26: =SUM(H21:H25) -> 2304066.7 | I26: =SUM(I21:I25) -> 2407066.7 | J26: =SUM(J21:J25) -> 2851066.7
C27: EBIT | H27: =H18-H26 -> 3630701.3 | I27: =I18-I26 -> 9801598.9 | J27: =J18-J26 -> 19124531
A29: Financial Health Metrics per Customer
C32: Items | H32: 2027 | I32: 2028 | J32: 2029
C33: Revenue per Guest | H33: =Assumptions!F67/Assumptions!F24 -> 711 | I33: =Assumptions!G67/Assumptions!G24 -> 711 | J33: =Assumptions!H67/Assumptions!H24 -> 711
C34: Revenue per Event | H34: =Assumptions!F67/Assumptions!F17 -> 106650 | I34: =Assumptions!G67/Assumptions!G17 -> 127980 | J34: =Assumptions!H67/Assumptions!H17 -> 153576
C35: Annual Recurring Revenue per Customer (ARR) | H35: =Assumptions!F67/Assumptions!F9 -> 746550 | I35: =Assumptions!G67/Assumptions!G9 -> 1023840 | J35: =Assumptions!H67/Assumptions!H9 -> 1382184
C36: Churn Rate | H36: 0.08 | I36: 0.07 | J36: 0.06
C37: Churned Customers | H37: =H36*Assumptions!F9 -> 0.64 | I37: =I36*Assumptions!G9 -> 0.84 | J37: =J36*Assumptions!H9 -> 0.96
C38: New Customers Acquired | H38: =Assumptions!G9-Assumptions!F9+H37 -> 4.64 | I38: =(Assumptions!H9-Assumptions!G9)+I37 -> 4.84 | J38: 5
C39: CAC | H39: =Assumptions!C156/H38 -> 127370.69 | I39: =Assumptions!D156/I38 -> 80371.901 | J39: =Assumptions!F156/J38 -> 90400
C40: LTV | H40: =H35*35%/H36 -> 3266156.2 | I40: =I35*35%/I36 -> 5119200 | J40: =J35*35%/J36 -> 8062740
C41: LTV/CAC Ratio | H41: =TEXT(H40/H39,0)&"x" -> 26x | I41: =TEXT(I40/I39,0)&"x" -> 64x | J41: =TEXT(J40/J39,0)&"x" -> 89x
C42: EBIT | H42: =H27/H6 -> 0.60791329 | I42: =I27/I6 -> 0.79778082 | J42: =J27/J6 -> 0.86477865
A44: Cash Flow Statement
...
